#VRML_SIM R2023b utf8
# license: Apache License 2.0
# license url: http://www.apache.org/licenses/LICENSE-2.0
# This is a proto file for Webots for the AbbIrb140
# Extracted from: D:/Work/python/handEye/abb_irb140_support_ROS/urdf/irb140.urdf
# python -m urdf2webots.importer --input=irb140.urdf --output=outputFile --normal --box-collision
# Not perfect, some errors needs to be fixed manually.


PROTO AbbIrb140_handslot [
  field  SFVec3f     translation     0 0 0
  field  SFRotation  rotation        0 0 1 0
  field  SFString    name            "AbbIrb140"  # Is `Robot.name`.
  field  SFString    controller      ""       	  # Is `Robot.controller`.
  field  MFString    controllerArgs  []           # Is `Robot.controllerArgs`.
  field  SFString    customData      ""           # Is `Robot.customData`.
  field  SFBool      supervisor      FALSE        # Is `Robot.supervisor`.
  field  SFBool      synchronization TRUE         # Is `Robot.synchronization`.
  field  SFBool      selfCollision   FALSE        # Is `Robot.selfCollision`.
  field MFNode     	 handSlot        []           # Extends the arm with new nodes in the hand slot.
]
{
  Robot {
    translation IS translation
    rotation IS rotation
	name IS name
    children [
      Transform {
        scale 0.010000 0.010000 0.010000
        children [
          Shape {
            appearance DEF abb_orange PBRAppearance {
              baseColor 1.000000 0.430000 0.000000
              roughness 1.000000
              metalness 0
            }
            geometry DEF base_link Mesh {
              url "../libraries/irb140_meshes/base_link.stl"
            }
          }
        ]
      }
      HingeJoint {
        jointParameters HingeJointParameters {
          axis 0.000000 0.000000 1.000000
        }
        device [
          RotationalMotor {
            name "joint_1"
            maxVelocity 2.618
            minPosition -3.1416
            maxPosition 3.1416
            maxTorque 10000
          }
          PositionSensor {
            name "joint_1_sensor"
          }
        ]
        endPoint Solid {
          children [
            Transform {
              scale 0.010000 0.010000 0.010000
              children [
                Shape {
                  appearance USE abb_orange
                  geometry DEF link_1 Mesh {
                    url "../libraries/irb140_meshes/link_1.stl"
                  }
                }
              ]
            }
            HingeJoint {
              jointParameters HingeJointParameters {
                axis 0.000000 1.000000 0.000000
                anchor 0.070000 0.000000 0.352000
              }
              device [
                RotationalMotor {
                  name "joint_2"
                  maxVelocity 2.618
                  minPosition -1.7453
                  maxPosition 1.7453
                  maxTorque 10000
                }
                PositionSensor {
                  name "joint_2_sensor"
                }
              ]
              endPoint Solid {
                translation 0.070000 0.000000 0.352000
                children [
                  Transform {
                    translation -0.070000 0.000000 -0.352000
                    scale 0.010000 0.010000 0.010000
                    children [
                      Shape {
                        appearance USE abb_orange
                        geometry DEF link_2 Mesh {
                          url "../libraries/irb140_meshes/link_2.stl"
                        }
                      }
                    ]
                  }
                  HingeJoint {
                    jointParameters HingeJointParameters {
                      axis 0.000000 1.000000 0.000000
                      anchor 0.000000 -0.065000 0.360000
                    }
                    device [
                      RotationalMotor {
                        name "joint_3"
                        maxVelocity 2.618
                        minPosition -2.4434
                        maxPosition 2.4434
                        maxTorque 10000
                      }
                      PositionSensor {
                        name "joint_3_sensor"
                      }
                    ]
                    endPoint Solid {
                      translation 0.000000 -0.065000 0.360000
                      children [
                        Transform {
                          translation -0.070000 0.065000 -0.712000
                          scale 0.010000 0.010000 0.010000
                          children [
                            Shape {
                              appearance USE abb_orange
                              geometry DEF link_3 Mesh {
                                url "../libraries/irb140_meshes/link_3.stl"
                              }
                            }
                          ]
                        }
                        HingeJoint {
                          jointParameters HingeJointParameters {
                            anchor 0.239000 0.065000 0.000000
                          }
                          device [
                            RotationalMotor {
                              name "joint_4"
                              maxVelocity 6.2832
                              minPosition -3.49
                              maxPosition 3.49
                              maxTorque 10000
                            }
                            PositionSensor {
                              name "joint_4_sensor"
                            }
                          ]
                          endPoint Solid {
                            translation 0.239000 0.065000 0.000000
                            children [
                              Transform {
                                translation -0.309000 0.000000 -0.712000
                                scale 0.010000 0.010000 0.010000
                                children [
                                  Shape {
                                    appearance USE abb_orange
                                    geometry DEF link_4 Mesh {
                                      url "../libraries/irb140_meshes/link_4.stl"
                                    }
									castShadows FALSE
                                  }
                                ]
                              }
                              HingeJoint {
                                jointParameters HingeJointParameters {
                                  axis 0.000000 1.000000 0.000000
                                  anchor 0.141000 0.000000 0.000000
                                }
                                device [
                                  RotationalMotor {
                                    name "joint_5"
                                    maxVelocity 6.2832
                                    minPosition -2.0071
                                    maxPosition 2.0071
                                    maxTorque 10000
                                  }
                                  PositionSensor {
                                    name "joint_5_sensor"
                                  }
                                ]
                                endPoint Solid {
                                  translation 0.141000 0.000000 0.000000
                                  children [
                                    Transform {
                                      translation -0.450000 0.000000 -0.712000
                                      scale 0.010000 0.010000 0.010000
                                      children [
                                        Shape {
                                          appearance USE abb_orange
                                          geometry DEF link_5 Mesh {
                                            url "../libraries/irb140_meshes/link_5.stl"
                                          }
                                        }
                                      ]
                                    }
                                    HingeJoint {
                                      jointParameters HingeJointParameters {
                                        anchor 0.065000 0.000000 0.000000
                                      }
                                      device [
                                        RotationalMotor {
                                          name "joint_6"
                                          maxVelocity 7.854
                                          minPosition -6.9813
                                          maxPosition 6.9813
                                          maxTorque 10000
                                        }
                                        PositionSensor {
                                          name "joint_6_sensor"
                                        }
                                      ]
                                      endPoint Solid {
                                        translation 0.065 0.000000 0.000000
                                        children [
                                          Transform {
                                            translation -0.02 0.0 0
                                            scale 1 1 1
                                            children [
                                              Shape {
                                                appearance USE abb_orange
                                                geometry DEF link_6 Mesh {
                                                  url "../libraries/irb140_meshes/link_6_scale_001.stl"
                                                }
                                              }
											  Transform {
												translation 0.02 0 0
												rotation 0 1 0 1.5708
												children IS handSlot
											  }
                                            ]
                                          }
                                        ]
                                        name "link_6"
                                        boundingObject Transform {
											translation 0 0 0
											children [
												Box {
													size 0.025, 0.050 ,0.050
												}
											]
										  }
                                        physics Physics {
                                        }
                                      }
                                    }
                                  ]
                                  name "link_5"
                                  boundingObject Transform {
									translation 0 0 0
									children [
										Box {
											size 0.084, 0.032, 0.084
										}
									]
								  }
                                  physics Physics {
                                  }
                                }
                              }
                            ]
                            name "link_4"
                            boundingObject Transform {
								translation 0.075 0 0
								children [
									Box {
										size 0.217, 0.134, 0.116
									}
								]
							  }
                            physics Physics {
                            }
                          }
                        }
                      ]
                      name "link_3"
                      boundingObject Transform {
						translation 0.05 0.075 0
						children [
							Box {
								size 0.386, 0.168, 0.200
							}
						]
					  }
                      physics Physics {
                      }
                    }
                  }
                ]
                name "link_2"
                boundingObject Transform {
					translation 0 -0.05 0.200
					children [
						Box {
							size 0.182, 0.250, 0.515
						}
					]
				  }
                physics Physics {
                }
              }
            }
          ]
          name "link_1"
          boundingObject Transform {
			translation 0 0 0.310
			children [
				Box {
					size 0.346, 0.380, 0.275
				}
			]
		  }
          physics Physics {
          }
        }
      }
    ]
	boundingObject Transform {
      translation -0.056 0 0.076
      children [
		Box {
		  size 0.487,0.401,0.152
		}
      ]
    }
	controller IS controller
    controllerArgs IS controllerArgs
    customData IS customData
    supervisor IS supervisor
    synchronization IS synchronization
    selfCollision IS selfCollision
  }
}